jax.errors.SimplifiedTraceback: For simplicity, JAX has removed its internal frames from the traceback of the following exception. Set JAX_TRACEBACK_FILTERING=off to include these.
The above exception was the direct cause of the following exception:
Traceback (most recent call last):
  File "/Users/benjamin/miniforge3/envs/siggame/lib/python3.9/site-packages/jax/_src/profiler.py", line 257, in trace
    yield
  File "/Users/benjamin/code/signification-game/base_experiment/ippo_ff.py", line 554, in main
    out = train(rng)
  File "/Users/benjamin/code/signification-game/base_experiment/ippo_ff.py", line 512, in train
    runner_state, traj_batch = jax.lax.scan( # Perform the update step for a specified number of updates and update the runner state
jaxlib.xla_extension.XlaRuntimeError: INTERNAL: Generated function failed: CpuCallback error: KeyboardInterrupt: <EMPTY MESSAGE>
At:
  /Users/benjamin/miniforge3/envs/siggame/lib/python3.9/site-packages/jax/_src/interpreters/mlir.py(2366): _wrapped_callback
  /Users/benjamin/miniforge3/envs/siggame/lib/python3.9/site-packages/jax/_src/interpreters/pxla.py(1151): __call__
  /Users/benjamin/miniforge3/envs/siggame/lib/python3.9/site-packages/jax/_src/profiler.py(336): wrapper
  /Users/benjamin/miniforge3/envs/siggame/lib/python3.9/site-packages/jax/_src/pjit.py(1185): _pjit_call_impl_python
  /Users/benjamin/miniforge3/envs/siggame/lib/python3.9/site-packages/jax/_src/pjit.py(1229): call_impl_cache_miss
  /Users/benjamin/miniforge3/envs/siggame/lib/python3.9/site-packages/jax/_src/pjit.py(1245): _pjit_call_impl
  /Users/benjamin/miniforge3/envs/siggame/lib/python3.9/site-packages/jax/_src/core.py(935): process_primitive
  /Users/benjamin/miniforge3/envs/siggame/lib/python3.9/site-packages/jax/_src/core.py(447): bind_with_trace
  /Users/benjamin/miniforge3/envs/siggame/lib/python3.9/site-packages/jax/_src/core.py(2740): bind
  /Users/benjamin/miniforge3/envs/siggame/lib/python3.9/site-packages/jax/_src/pjit.py(168): _python_pjit_helper
  /Users/benjamin/miniforge3/envs/siggame/lib/python3.9/site-packages/jax/_src/pjit.py(257): cache_miss
  /Users/benjamin/miniforge3/envs/siggame/lib/python3.9/site-packages/jax/_src/traceback_util.py(179): reraise_with_filtered_traceback
  /Users/benjamin/miniforge3/envs/siggame/lib/python3.9/site-packages/jax/_src/dispatch.py(87): apply_primitive
  /Users/benjamin/miniforge3/envs/siggame/lib/python3.9/site-packages/jax/_src/core.py(935): process_primitive
  /Users/benjamin/miniforge3/envs/siggame/lib/python3.9/site-packages/jax/_src/core.py(447): bind_with_trace
  /Users/benjamin/miniforge3/envs/siggame/lib/python3.9/site-packages/jax/_src/core.py(2740): bind
  /Users/benjamin/miniforge3/envs/siggame/lib/python3.9/site-packages/jax/_src/lax/control_flow/loops.py(1130): scan_bind
  /Users/benjamin/miniforge3/envs/siggame/lib/python3.9/site-packages/jax/_src/lax/control_flow/loops.py(273): scan
  /Users/benjamin/miniforge3/envs/siggame/lib/python3.9/site-packages/jax/_src/traceback_util.py(179): reraise_with_filtered_traceback
  /Users/benjamin/code/signification-game/base_experiment/ippo_ff.py(512): train
  /Users/benjamin/code/signification-game/base_experiment/ippo_ff.py(554): main
  /Users/benjamin/miniforge3/envs/siggame/lib/python3.9/site-packages/hydra/core/utils.py(186): run_job
  /Users/benjamin/miniforge3/envs/siggame/lib/python3.9/site-packages/hydra/_internal/hydra.py(119): run
  /Users/benjamin/miniforge3/envs/siggame/lib/python3.9/site-packages/hydra/_internal/utils.py(458): <lambda>
  /Users/benjamin/miniforge3/envs/siggame/lib/python3.9/site-packages/hydra/_internal/utils.py(220): run_and_report
  /Users/benjamin/miniforge3/envs/siggame/lib/python3.9/site-packages/hydra/_internal/utils.py(457): _run_app
  /Users/benjamin/miniforge3/envs/siggame/lib/python3.9/site-packages/hydra/_internal/utils.py(394): _run_hydra
  /Users/benjamin/miniforge3/envs/siggame/lib/python3.9/site-packages/hydra/main.py(94): decorated_main
  /Users/benjamin/code/signification-game/base_experiment/ippo_ff.py(559): <module>
During handling of the above exception, another exception occurred:
Traceback (most recent call last):
  File "/Users/benjamin/code/signification-game/base_experiment/ippo_ff.py", line 559, in <module>
    main()
  File "/Users/benjamin/miniforge3/envs/siggame/lib/python3.9/site-packages/hydra/main.py", line 94, in decorated_main
    _run_hydra(
  File "/Users/benjamin/miniforge3/envs/siggame/lib/python3.9/site-packages/hydra/_internal/utils.py", line 394, in _run_hydra
    _run_app(
  File "/Users/benjamin/miniforge3/envs/siggame/lib/python3.9/site-packages/hydra/_internal/utils.py", line 457, in _run_app
    run_and_report(
  File "/Users/benjamin/miniforge3/envs/siggame/lib/python3.9/site-packages/hydra/_internal/utils.py", line 220, in run_and_report
    return func()
  File "/Users/benjamin/miniforge3/envs/siggame/lib/python3.9/site-packages/hydra/_internal/utils.py", line 458, in <lambda>
    lambda: hydra.run(
  File "/Users/benjamin/miniforge3/envs/siggame/lib/python3.9/site-packages/hydra/_internal/hydra.py", line 119, in run
    ret = run_job(
  File "/Users/benjamin/miniforge3/envs/siggame/lib/python3.9/site-packages/hydra/core/utils.py", line 186, in run_job
    ret.return_value = task_function(task_cfg)
  File "/Users/benjamin/code/signification-game/base_experiment/ippo_ff.py", line 555, in main
    print("Done")
  File "/Users/benjamin/miniforge3/envs/siggame/lib/python3.9/contextlib.py", line 137, in __exit__
    self.gen.throw(typ, value, traceback)
  File "/Users/benjamin/miniforge3/envs/siggame/lib/python3.9/site-packages/jax/_src/profiler.py", line 259, in trace
    stop_trace()
  File "/Users/benjamin/miniforge3/envs/siggame/lib/python3.9/site-packages/jax/_src/profiler.py", line 206, in stop_trace
    sess.export(sess.stop(), _profile_state.log_dir)
KeyboardInterrupt